<?xml version="1.0" encoding="utf-8"?>
<!-- This URDF was automatically created by SolidWorks to URDF Exporter! Originally created by Stephen Brawner (brawner@gmail.com) 
     Commit Version: 1.5.1-0-g916b5db  Build Version: 1.5.7152.31018
     For more information, please see http://wiki.ros.org/sw_urdf_exporter -->
<robot
  name="cybertruck_4wd">

  <!-- Dummy Link -->
  <link name="base_footprint" />

  <joint name="base_footprint_joint" type="fixed">
    <parent link="base_footprint" />
    <child link="base_link" />
  </joint>

  <link
    name="base_link">
    <inertial>
      <origin
        xyz="0.0011659 2.7319E-16 0.019106"
        rpy="0 0 0" />
      <mass
        value="8.551" />
      <inertia
        ixx="0.022542"
        ixy="-2.3937E-16"
        ixz="-0.00037292"
        iyy="0.090783"
        iyz="1.8097E-16"
        izz="0.10362" />
    </inertial>
    <visual>
      <origin
        xyz="0 0 0"
        rpy="0 0 0" />
      <geometry>
        <mesh
          filename="package://cybertruck_4wd/meshes/base_link.STL" />
      </geometry>
      <material
        name="">
        <color
          rgba="0.74 0.75 0.79 1" />
      </material>
    </visual>
    <collision>
      <origin
        xyz="0 0 0"
        rpy="0 0 0" />
      <geometry>
        <mesh
          filename="package://cybertruck_4wd/meshes/base_link.STL" />
      </geometry>
    </collision>
  </link>
  <link
    name="front_right_wheel">
    <inertial>
      <origin
        xyz="-0.019538 8.6042E-16 -2.0539E-15"
        rpy="0 0 0" />
      <mass
        value="0.16011" />
      <inertia
        ixx="0.00023914"
        ixy="-7.1837E-19"
        ixz="1.3114E-18"
        iyy="0.00013245"
        iyz="4.0658E-20"
        izz="0.00013245" />
    </inertial>
    <visual>
      <origin
        xyz="0 0 0"
        rpy="0 0 0" />
      <geometry>
        <mesh
          filename="package://cybertruck_4wd/meshes/front_right_wheel.STL" />
      </geometry>
      <material
        name="">
        <color
          rgba="0 0 0 1" />
      </material>
    </visual>
    <collision>
      <origin
        xyz="0 0 0"
        rpy="0 0 0" />
      <geometry>
        <mesh
          filename="package://cybertruck_4wd/meshes/front_right_wheel.STL" />
      </geometry>
    </collision>
  </link>
  <joint
    name="front_right_joint"
    type="continuous">
    <origin
      xyz="0.18 -0.095 0"
      rpy="2.7426 0 1.5708" />
    <parent
      link="base_link" />
    <child
      link="front_right_wheel" />
    <axis
      xyz="1 0 0" />
  </joint>
  <link
    name="front_left_wheel">
    <inertial>
      <origin
        xyz="-0.019538 -8.3267E-17 -9.7534E-16"
        rpy="0 0 0" />
      <mass
        value="0.16011" />
      <inertia
        ixx="0.00023914"
        ixy="3.5138E-20"
        ixz="1.4771E-18"
        iyy="0.00013245"
        iyz="2.7048E-20"
        izz="0.00013245" />
    </inertial>
    <visual>
      <origin
        xyz="0 0 0"
        rpy="0 0 0" />
      <geometry>
        <mesh
          filename="package://cybertruck_4wd/meshes/front_left_wheel.STL" />
      </geometry>
      <material
        name="">
        <color
          rgba="0 0 0 1" />
      </material>
    </visual>
    <collision>
      <origin
        xyz="0 0 0"
        rpy="0 0 0" />
      <geometry>
        <mesh
          filename="package://cybertruck_4wd/meshes/front_left_wheel.STL" />
      </geometry>
    </collision>
  </link>
  <joint
    name="front_left_joint"
    type="continuous">
    <origin
      xyz="0.18 0.095 0"
      rpy="0 0 -1.5708" />
    <parent
      link="base_link" />
    <child
      link="front_left_wheel" />
    <axis
      xyz="-1 0 0" />
  </joint>
  <link
    name="rear_right_wheel">
    <inertial>
      <origin
        xyz="-0.019538 2.7756E-16 9.2981E-16"
        rpy="0 0 0" />
      <mass
        value="0.16011" />
      <inertia
        ixx="0.00023914"
        ixy="-4.7384E-19"
        ixz="-1.4572E-18"
        iyy="0.00013245"
        iyz="4.4046E-20"
        izz="0.00013245" />
    </inertial>
    <visual>
      <origin
        xyz="0 0 0"
        rpy="0 0 0" />
      <geometry>
        <mesh
          filename="package://cybertruck_4wd/meshes/rear_right_wheel.STL" />
      </geometry>
      <material
        name="">
        <color
          rgba="0 0 0 1" />
      </material>
    </visual>
    <collision>
      <origin
        xyz="0 0 0"
        rpy="0 0 0" />
      <geometry>
        <mesh
          filename="package://cybertruck_4wd/meshes/rear_right_wheel.STL" />
      </geometry>
    </collision>
  </link>
  <joint
    name="rear_right_joint"
    type="continuous">
    <origin
      xyz="-0.18 -0.0950000000000009 0"
      rpy="0.351527640558485 0 1.5707963267949" />
    <parent
      link="base_link" />
    <child
      link="rear_right_wheel" />
    <axis
      xyz="1 0 0" />
  </joint>
  <link
    name="rear_left_wheel">
    <inertial>
      <origin
        xyz="-0.019538 3.3307E-16 -2.2135E-15"
        rpy="0 0 0" />
      <mass
        value="0.16011" />
      <inertia
        ixx="0.00023914"
        ixy="-2.0548E-19"
        ixz="1.4933E-18"
        iyy="0.00013245"
        iyz="2.7105E-20"
        izz="0.00013245" />
    </inertial>
    <visual>
      <origin
        xyz="0 0 0"
        rpy="0 0 0" />
      <geometry>
        <mesh
          filename="package://cybertruck_4wd/meshes/rear_left_wheel.STL" />
      </geometry>
      <material
        name="">
        <color
          rgba="0 0 0 1" />
      </material>
    </visual>
    <collision>
      <origin
        xyz="0 0 0"
        rpy="0 0 0" />
      <geometry>
        <mesh
          filename="package://cybertruck_4wd/meshes/rear_left_wheel.STL" />
      </geometry>
    </collision>
  </link>
  <joint
    name="rear_left_joint"
    type="continuous">
    <origin
      xyz="-0.18 0.095 0"
      rpy="-0.16173 0 -1.5708" />
    <parent
      link="base_link" />
    <child
      link="rear_left_wheel" />
    <axis
      xyz="-1 0 0" />
  </joint>


  <!-- Hokuyo Laser -->
  <link name="hokuyo">
    <collision>
      <origin xyz="0 0 0" rpy="0 0 0"/>
      <geometry>
    <box size="0.1 0.1 0.1"/>
      </geometry>
    </collision>

    <visual>
      <origin xyz="0 0 0" rpy="0 0 0"/>
      <geometry>
        <mesh filename="package://cybertruck_4wd/meshes/hokuyo.dae"/>
      </geometry>
    </visual>

    <inertial>
      <mass value="1e-5" />
      <origin xyz="0 0 0" rpy="0 0 0"/>
      <inertia ixx="1e-6" ixy="0" ixz="0" iyy="1e-6" iyz="0" izz="1e-6" />
    </inertial>
  </link>

  <joint name="hokuyo_joint" type="fixed">
    <origin xyz="0.09 0 0.09" rpy="0 0 0"/>
    <parent link="base_footprint"/>
    <child link="hokuyo"/>
  </joint>


  <!-- Skid Steering Drive -->
  <gazebo>
    <plugin name="skid_steer_drive_controller" filename="libgazebo_ros_skid_steer_drive.so">
      <updateRate>100.0</updateRate>
      <robotNamespace>/</robotNamespace>
      <leftFrontJoint>front_left_joint</leftFrontJoint>
      <rightFrontJoint>front_right_joint</rightFrontJoint>
      <leftRearJoint>rear_left_joint</leftRearJoint>
      <rightRearJoint>rear_right_joint</rightRearJoint>
      <wheelSeparation>0.4</wheelSeparation>
      <wheelDiameter>0.215</wheelDiameter>
      <robotBaseFrame>base_footprint</robotBaseFrame>
      <torque>20</torque>
      <topicName>cmd_vel</topicName>
      <broadcastTF>true</broadcastTF>
    </plugin>
  </gazebo>

  <!-- Hokuyo Laser Sensor -->
  <gazebo reference="hokuyo">
    <sensor type="gpu_ray" name="head_hokuyo_sensor">
      <pose>0 0 0 0 0 0</pose>
      <visualize>false</visualize>
      <update_rate>40</update_rate>
      <ray>
        <scan>
          <horizontal>
            <samples>720</samples>
            <resolution>1</resolution>
            <min_angle>-1.570796</min_angle>
            <max_angle>1.570796</max_angle>
          </horizontal>
        </scan>
        <range>
          <min>0.10</min>
          <max>30.0</max>
          <resolution>0.01</resolution>
        </range>
        <noise>
          <type>gaussian</type>
          <!-- Noise parameters based on published spec for Hokuyo laser
               achieving "+-30mm" accuracy at range < 10m.  A mean of 0.0m and
               stddev of 0.01m will put 99.7% of samples within 0.03m of the true
               reading. -->
          <mean>0.0</mean>
          <stddev>0.01</stddev>
        </noise>
      </ray>
      <plugin name="gazebo_ros_head_hokuyo_controller" filename="libgazebo_ros_gpu_laser.so">
        <topicName>/scan</topicName>
        <frameName>hokuyo</frameName>
      </plugin>
    </sensor>
  </gazebo>

</robot>
